Workbook

Sheet FAME Persistence2
A1: 53 | B1: MonthlyData
A2: MonthlyFAME | B2: $A$7 | C2: A1:A780 | D2: 21946 | E2: 45471.465 | F2: TRUE | G2: FAMEDATE | H2: 1960 | I2: 2024 | J2: 0 | K2: m | L2: FALSE | M2: FALSE | N2: FALSE
A3: MonthlyFAME | B3: $B$7 | C3: A1:A780 | E3: 45471.465 | F3: TRUE | G3: ecy2.m | H3: 1960 | I3: 2024 | J3: 0 | K3: m | L3: FALSE | M3: FALSE | N3: FALSE
A4: MonthlyFAME | B4: $C$7 | C4: A1:A780 | E4: 45471.465 | F4: TRUE | G4: totexq1.m | H4: 1960 | I4: 2024 | J4: 0 | K4: m | L4: FALSE | M4: FALSE | N4: FALSE
A5: MonthlyFAME | B5: $D$7 | C5: A1:A780 | E5: 45471.465 | F5: TRUE | G5: totreq1.m | H5: 1960 | I5: 2024 | J5: 0 | K5: m | L5: FALSE | M5: FALSE | N5: FALSE
A6: MonthlyFAME | B6: $E$7 | C6: A1:A780 | E6: 45471.465 | F6: TRUE | G6: cbiout.m | H6: 1960 | I6: 2024 | J6: 0 | K6: m | L6: FALSE | M6: FALSE | N6: FALSE
A7: MonthlyFAME | B7: $F$7 | C7: A1:A780 | E7: 45471.465 | F7: TRUE | G7: cipsmba.m | H7: 1960 | I7: 2024 | J7: 0 | K7: m | L7: FALSE | M7: FALSE | N7: FALSE
A8: MonthlyFAME | B8: $G$7 | C8: A1:A780 | E8: 45471.465 | F8: TRUE | G8: CIPSSBA.m | H8: 1960 | I8: 2024 | J8: 0 | K8: m | L8: FALSE | M8: FALSE | N8: FALSE
A9: MonthlyFAME | B9: $H$7 | C9: A1:A780 | E9: 45471.465 | F9: TRUE | G9: CIPSCBA.m | H9: 1960 | I9: 2024 | J9: 0 | K9: m | L9: FALSE | M9: FALSE | N9: FALSE
A10: MonthlyFAME | B10: $I$7 | C10: A1:A780 | E10: 45471.465 | F10: TRUE | G10: gfkecbalsa.m | H10: 1960 | I10: 2024 | J10: 0 | K10: m | L10: FALSE | M10: FALSE | N10: FALSE
A11: MonthlyFAME | B11: $J$7 | C11: A1:A780 | D11: 41.3 | E11: 45471.465 | F11: TRUE | G11: k222.m | H11: 1960 | I11: 2024 | J11: 0 | K11: m | L11: FALSE | M11: FALSE | N11: FALSE
A12: MonthlyFAME | B12: $K$7 | C12: A1:A780 | E12: 45471.465 | F12: TRUE | G12: ecyc_dp.m | H12: 1960 | I12: 2024 | J12: 0 | K12: m | L12: FALSE | M12: FALSE | N12: FALSE
A13: MonthlyFAME | B13: $L$7 | D13: #N/A | E13: 0 | F13: TRUE | G13: x12(TOTCARS.M,mult,$A$2,L) | H13: 1960 | I13: 2024 | J13: 0 | K13: m | L13: FALSE | M13: FALSE | N13: FALSE
A14: MonthlyFAME | B14: $M$7 | C14: A1:A780 | E14: 45471.465 | F14: TRUE | G14: bqkq.m | H14: 1960 | I14: 2024 | J14: 0 | K14: m | L14: FALSE | M14: FALSE | N14: FALSE
A15: MonthlyFAME | B15: $N$7 | C15: A1:A780 | E15: 45471.465 | F15: TRUE | G15: bqko.m | H15: 1960 | I15: 2024 | J15: 0 | K15: m | L15: FALSE | M15: FALSE | N15: FALSE
A16: MonthlyFAME | B16: $O$7 | C16: A1:A780 | E16: 45471.465 | F16: TRUE | G16: 100*mgsc.m[t-1]/(mgrz.m[t-1]+mgsc.m[t-1]) | H16: 1960 | I16: 2024 | J16: 0 | K16: m | L16: FALSE | M16: FALSE | N16: FALSE
A17: MonthlyFAME | B17: $P$7 | C17: A1:A780 | E17: 45471.465 | F17: TRUE | G17: mgrz.m[t-1] | H17: 1960 | I17: 2024 | J17: 0 | K17: m | L17: FALSE | M17: FALSE | N17: FALSE
A18: MonthlyFAME | B18: $Q$7 | C18: A1:A780 | E18: 45471.465 | F18: TRUE | G18: ybus.m[t-1] | H18: 1960 | I18: 2024 | J18: 0 | K18: m | L18: FALSE | M18: FALSE | N18: FALSE
A19: MonthlyFAME | B19: $R$7 | C19: A1:A780 | E19: 45471.465 | F19: TRUE | G19: ap2y.m[t-1] | H19: 1960 | I19: 2024 | J19: 0 | K19: m | L19: FALSE | M19: FALSE | N19: FALSE
A20: MonthlyFAME | B20: $S$7 | C20: A1:A780 | E20: 45471.465 | F20: TRUE | G20: overlay(kab9_hist.m,kab9_dp.m) | H20: 1960 | I20: 2024 | J20: 0 | K20: m | L20: FALSE | M20: FALSE | N20: FALSE
A21: MonthlyFAME | B21: $T$7 | C21: A1:A780 | E21: 45471.465 | F21: TRUE | G21: bcjd.m | H21: 1960 | I21: 2024 | J21: 0 | K21: m | L21: FALSE | M21: FALSE | N21: FALSE
A22: MonthlyFAME | B22: $U$7 | D22: #N/A | E22: 0 | F22: TRUE | G22: x12(d7bt3dpm.m,mult,$A$2,L) | H22: 1960 | I22: 2024 | J22: 0 | K22: m | L22: FALSE | M22: FALSE | N22: FALSE
A23: MonthlyFAME | B23: $V$7 | D23: #N/A | E23: 0 | F23: TRUE | G23: x12(d7bt3dpm.m,mult,$A$2,L) | H23: 1960 | I23: 2024 | J23: 0 | K23: m | L23: FALSE | M23: FALSE | N23: FALSE
A24: MonthlyFAME | B24: $W$7 | D24: #N/A | E24: 0 | F24: TRUE | G24: x12(chaw.m,mult,$A$2,L) | H24: 1960 | I24: 2024 | J24: 0 | K24: m | L24: FALSE | M24: FALSE | N24: FALSE
A25: MonthlyFAME | B25: $X$7 | D25: #N/A | E25: 0 | F25: TRUE | G25: x12(chmk.m,mult,$A$2,L) | H25: 1960 | I25: 2024 | J25: 0 | K25: m | L25: FALSE | M25: FALSE | N25: FALSE
A26: MonthlyFAME | B26: $Y$7 | D26: #N/A | E26: 0 | F26: TRUE | G26: x12(gb7s.m,mult,$A$2,L) | H26: 1960 | I26: 2024 | J26: 0 | K26: m | L26: FALSE | M26: FALSE | N26: FALSE
A27: MonthlyFAME | B27: $Z$7 | D27: #N/A | E27: 0 | F27: TRUE | G27: x12(ghip.m,mult,$A$2,L) | H27: 1960 | I27: 2024 | J27: 0 | K27: m | L27: FALSE | M27: FALSE | N27: FALSE
A28: MonthlyFAME | B28: $AA$7 | D28: #N/A | E28: 0 | F28: TRUE | G28: x12(NWHPISA.M,mult,$A$2,L) | H28: 1960 | I28: 2024 | J28: 0 | K28: m | L28: FALSE | M28: FALSE | N28: FALSE
A29: MonthlyFAME | B29: $AB$7 | C29: A1:A780 | E29: 45471.466 | F29: TRUE | G29: conv2ma(oilbrnp_p.B) | H29: 1960 | I29: 2024 | J29: 0 | K29: m | L29: FALSE | M29: FALSE | N29: FALSE
A30: MonthlyFAME | B30: $AC$7 | C30: A1:A780 | E30: 45471.466 | F30: TRUE | G30: M4SA.M | H30: 1960 | I30: 2024 | J30: 0 | K30: m | L30: FALSE | M30: FALSE | N30: FALSE
A31: MonthlyFAME | B31: $AD$7 | C31: A1:A780 | E31: 45471.466 | F31: TRUE | G31: vtvx.m | H31: 1960 | I31: 2024 | J31: 0 | K31: m | L31: FALSE | M31: FALSE | N31: FALSE
A32: MonthlyFAME | B32: $AE$7 | C32: A1:A780 | E32: 45471.466 | F32: TRUE | G32: conv2ma(ukbrbase.b) | H32: 1960 | I32: 2024 | J32: 0 | K32: m | L32: FALSE | M32: FALSE | N32: FALSE
A33: MonthlyFAME | B33: $AF$7 | C33: A1:A780 | E33: 45471.466 | F33: TRUE | G33: conv2ma(BP0003M.B) | H33: 1960 | I33: 2024 | J33: 0 | K33: m | L33: FALSE | M33: FALSE | N33: FALSE
A34: MonthlyFAME | B34: $AG$7 | C34: A1:A780 | E34: 45471.466 | F34: TRUE | G34: conv2ma(seri.b) | H34: 1960 | I34: 2024 | J34: 0 | K34: m | L34: FALSE | M34: FALSE | N34: FALSE
A35: MonthlyFAME | B35: $AH$7 | C35: A1:A780 | E35: 45471.466 | F35: TRUE | G35: conv2ma(asx.b) | H35: 1960 | I35: 2024 | J35: 0 | K35: m | L35: FALSE | M35: FALSE | N35: FALSE
A36: MonthlyFAME | B36: $AI$7 | C36: A1:A780 | E36: 45471.466 | F36: TRUE | G36: conv2ma(mcx.b) | H36: 1960 | I36: 2024 | J36: 0 | K36: m | L36: FALSE | M36: FALSE | N36: FALSE
A37: MonthlyFAME | B37: $AJ$7 | C37: A1:A780 | E37: 45471.466 | F37: TRUE | G37: conv2ma(ukfoceq.b) | H37: 1960 | I37: 2024 | J37: 0 | K37: m | L37: FALSE | M37: FALSE | N37: FALSE
A38: MonthlyFAME | B38: $AK$7 | C38: A1:A780 | E38: 45471.466 | F38: TRUE | G38: conv2ma(spx.b) | H38: 1960 | I38: 2024 | J38: 0 | K38: m | L38: FALSE | M38: FALSE | N38: FALSE
A39: MonthlyFAME | B39: $AL$7 | C39: A1:A780 | E39: 45471.466 | F39: TRUE | G39: conv2ma(djeurst_pi.B) | H39: 1960 | I39: 2024 | J39: 0 | K39: m | L39: FALSE | M39: FALSE | N39: FALSE
A40: MonthlyFAME | B40: $AM$7 | C40: A1:A780 | E40: 45471.466 | F40: TRUE | G40: conv2ma(vix.b) | H40: 1960 | I40: 2024 | J40: 0 | K40: m | L40: FALSE | M40: FALSE | N40: FALSE
...

Sheet MonthlyFAME
C1: Production, Services and Trade | H1: Labour market | N1: Prices
A2: 1960 | C2: UK INDEX OF PRODUCTION - ALL PRODUCTION INDUSTRIES VOLA | D2: UK INDEX OF SERVICES - TOTAL VOLA | E2: New Cars Registrations | F2: UK ITS EXPORTS F.O.B. TOTAL CURA | G2: UK ITS IMPORTS C.I.F. TOTAL CURA | H2: UK LFS: UNEMPLOYMENT RATE, ALL, AGED 16 & OVER SADJ | I2: UK LFS: IN EMPLOYMENT, ALL, AGED 16-64 VOLA | J2: HOURS WORKED | K2: UK JOB VACANCIES (STANDARDIZED) VOLA | L2: Average Weekly Earnings | M2: Claimant Count Rate | N2: CPI all items | O2: Core CPI | P2: RPI all items | Q2: RPI ex Mortgages Interest Payments (RPIX) | R2: PPI Output | S2: PPI Input | T2: Nationwide House Price MoM | U2: Oil Brent | AA2: UK BOE AGENTS SCORES: TURNOVER - CONSUMER SERVICES NADJ | AB2: UK GDP: GROSS VALUE ADDED (BASIC PRICES) VOLA | AC2: Unemployment Rate (Ry’s long run series) | AD2: Vacancies (Ry’s Long Run Series) | AE2: Index of Production (Ry’s LR series (not sure if it’s needed)
A3: 2024 | B3: 1 | C3: 9 | D3: 10 | E3: 11 | F3: 12 | G3: 13 | H3: 14 | I3: 15 | J3: 16 | K3: 17 | L3: 18 | M3: 19 | N3: 20 | O3: 21 | P3: 22 | Q3: 23 | R3: 24 | S3: 25 | T3: 26 | U3: 27
B4: SA | C4: SA | D4: SA | E4: SA | F4: SA | G4: SA | H4: SA | I4: SA | K4: SA | L4: SA | M4: x12 | N4: x12 | O4: x12 | P4: x12 | Q4: x12 | R4: x12 | S4: x12
A5: m | B5: GDP_M | C5: IoP | D5: IoS | F5: Exports | G5: Imports | H5: UR | I5: EMP | J5: Hours | K5: Vacancies | N5: CPI | AA5: BOEAS_CS | AB5: GVA | AC5: =[1]RawData!AD3 -> UR_RY | AD5: =[1]RawData!AE3 -> Vacancies_RY | AE5: IoP_RY
B6: ecy2.m | C6: k222.m | D6: ecyc_dp.m | E6: x12(TOTCARS.M,mult,$A$2,L) | F6: bqkq.m | G6: bqko.m | H6: 100*mgsc.m[t-1]/(mgrz.m[t-1]+mgsc.m[t-1]) | I6: mgrz.m[t-1] | J6: ybus.m[t-1] | K6: ap2y.m[t-1] | L6: overlay(kab9_hist.m,kab9_dp.m) | M6: bcjd.m | N6: x12(d7bt3dpm.m,mult,$A$2,L) | O6: x12(d7bt3dpm.m,mult,$A$2,L) | P6: x12(chaw.m,mult,$A$2,L) | Q6: x12(chmk.m,mult,$A$2,L) | R6: x12(gb7s.m,mult,$A$2,L) | S6: x12(ghip.m,mult,$A$2,L) | T6: x12(NWHPISA.M,mult,$A$2,L) | U6: conv2ma(oilbrnp_p.B)
A7: =[2]!FAMEData("FAMEDATE",A2,A3, 0,A5, "Down", "No Heading", "Normal") -> #NAME? | B7: =[2]!FAMEData(B6, $A$2, $A$3, 0,$A$5,"Down","No Heading","Normal") -> #NAME? | C7: =[2]!FAMEData(C6, $A$2, $A$3, 0,$A$5,"Down","No Heading","Normal") -> #NAME? | D7: =[2]!FAMEData(D6, $A$2, $A$3, 0,$A$5,"Down","No Heading","Normal") -> #NAME? | E7: =[2]!FAMEData(E6, $A$2, $A$3, 0,$A$5,"Down","No Heading","Normal") -> #NAME? | F7: =[2]!FAMEData(F6, $A$2, $A$3, 0,$A$5,"Down","No Heading","Normal") -> #NAME? | G7: =[2]!FAMEData(G6, $A$2, $A$3, 0,$A$5,"Down","No Heading","Normal") -> #NAME? | H7: =[2]!FAMEData(H6, $A$2, $A$3, 0,$A$5,"Down","No Heading","Normal") -> #NAME? | I7: =[2]!FAMEData(I6, $A$2, $A$3, 0,$A$5,"Down","No Heading","Normal") -> #NAME? | ... U7: =[2]!FAMEData(U6, $A$2, $A$3, 0,$A$5,"Down","No Heading","Normal") -> #NAME?
A8: 21975 | C8: 41.3 | AB8: =[2]!FAMEData(AB7, $A$2, $A$3, 0,$A$5,"Down","No Heading","Normal") -> #NAME? | AC8: =[2]!FAMEData(AC7, $A$2, $A$3, 0,$A$5,"Down","No Heading","Normal") -> #NAME?
A9: 22006 | C9: 41.3
A10: 22036 | C10: 41.3
A11: 22067 | C11: 41.3
A12: 22097 | C12: 41.3
A13: 22128 | C13: 41.3
A14: 22159 | C14: 41.4
A15: 22189 | C15: 41.7
A16: 22220 | C16: 41.9
A17: 22250 | C17: 41.9
A18: 22281 | C18: 41.7
A19: 22312 | C19: 41.3
A20: 22340 | C20: 41.1
... A42: 23011 | C42: 41.7
A43: 23042 | C43: 41.4 | L43: 10.557267
A44: 23070 | C44: 41.4 | L44: 10.62593
A45: 23101 | C45: 41.8 | L45: 10.48111
A46: 23131 | C46: 42.3 | L46: 10.492773
A47: 23162 | C47: 42.9 | L47: 10.585569
A48: 23192 | C48: 43.5 | L48: 10.774261
A49: 23223 | C49: 43.9 | L49: 10.841342
A50: 23254 | C50: 44.2 | L50: 11.065232
A51: 23284 | C51: 44.4 | L51: 10.773488
A52: 23315 | C52: 44.6 | L52: 10.753324
A53: 23345 | C53: 45 | L53: 11.004215
A54: 23376 | C54: 45.5 | L54: 11.431966
... A138: 25933 | C138: 55.5 | L138: 19.289937
A139: 25964 | C139: 55.8 | L139: 19.667394 | M139: 533.6
A140: 25992 | C140: 54.7 | L140: 19.759731 | M140: 552.3
A141: 26023 | C141: 54 | H141: 3.829172 | I141: 24613 | J141: 864.3 | L141: 19.821442 | M141: 573.5
A142: 26053 | C142: 54.8 | H142: 3.9025535 | I142: 24575 | J142: 862.7 | L142: 19.846515 | M142: 599.1
A143: 26084 | C143: 55.1 | H143: 3.9989055 | I143: 24559 | J143: 862.5 | L143: 20.211309 | M143: 641.7
A144: 26114 | C144: 54.9 | H144: 4.0818718 | I144: 24556 | J144: 862.8 | L144: 20.37123 | M144: 655.2
...

Sheet MonthlyData
A1: 1960 | B1: GDP | C1: Production, Services, Trade | G1: Labour market | M1: Prices
A2: 2021 | B2: UK GDP monthly, SA | C2: UK INDEX OF PRODUCTION - ALL PRODUCTION INDUSTRIES VOLA | D2: UK INDEX OF SERVICES - TOTAL VOLA | E2: UK ITS EXPORTS F.O.B. TOTAL CURA | F2: UK ITS IMPORTS C.I.F. TOTAL CURA | G2: UK LFS: UNEMPLOYMENT RATE, ALL, AGED 16 & OVER SADJ | H2: UK LFS: IN EMPLOYMENT, ALL, AGED 16-64 VOLA | I2: HOURS WORKED | J2: UK JOB VACANCIES (STANDARDIZED) VOLA | K2: Average Weekly Earnings | L2: Claimant Count Rate | M2: CPI all items | N2: Core CPI | O2: RPI all items | P2: RPI ex Mortgages Interest Payments (RPIX) | Q2: PPI Output | R2: PPI Input | S2: Nationwide House Price MoM | T2: Oil Brent
A3: count | B3: 1 | C3: 9 | D3: 10 | E3: 11 | F3: 12 | G3: 13 | H3: 14 | I3: 15 | J3: 16 | K3: 17 | L3: 18 | M3: 19 | N3: 20 | O3: 21 | P3: 22 | Q3: 23 | R3: 24 | S3: 25 | T3: 26
A4: m | B4: GDP_M | C4: IoP | D4: IoS | E4: Exp | F4: Imp | G4: UR | H4: EMP | I4: Hours | J4: Vacancies | K4: AWE | L4: Claimant | M4: CPI | N4: CoreCPI | O4: RPI | P4: RPIX | Q4: PPIout | R4: PPIin | S4: HPr | T4: Oil
A5: transform | B5: 3 | C5: 3 | D5: 3 | E5: 3 | F5: 3 | G5: 0 | H5: 3 | I5: 3 | J5: 3 | K5: 3 | L5: 0 | M5: 3 | N5: 3 | O5: 3 | P5: 3 | Q5: 3 | R5: 3 | S5: 2 | T5: 3
A6: =IF(MonthlyFAME!A8=0,"",MonthlyFAME!A8) -> 21975 | B6: =IF(MonthlyFAME!B8=0,"",MonthlyFAME!B8) | C6: =IF(MonthlyFAME!C8=0,"",MonthlyFAME!C8) -> 41.3 | D6: =IF(MonthlyFAME!D8=0,"",MonthlyFAME!D8) | E6: =IF(MonthlyFAME!F8=0,"",MonthlyFAME!F8) | F6: =IF(MonthlyFAME!G8=0,"",MonthlyFAME!G8) | G6: =IF(MonthlyFAME!H8=0,"",MonthlyFAME!H8) | H6: =IF(MonthlyFAME!I8=0,"",MonthlyFAME!I8) | I6: =IF(MonthlyFAME!J8=0,"",MonthlyFAME!J8) | K6: =IF(MonthlyFAME!L8=0,"",MonthlyFAME!L8) | L6: =IF(MonthlyFAME!M8=0,"",MonthlyFAME!M8) | M6: =IF(MonthlyFAME!N8=0,"",MonthlyFAME!N8) | N6: =IF(MonthlyFAME!O8=0,"",MonthlyFAME!O8) | O6: =IF(MonthlyFAME!P8=0,"",MonthlyFAME!P8) | P6: =IF(MonthlyFAME!Q8=0,"",MonthlyFAME!Q8) | Q6: =IF(MonthlyFAME!R8=0,"",MonthlyFAME!R8) | R6: =IF(MonthlyFAME!S8=0,"",MonthlyFAME!S8) | ... T6: =IF(MonthlyFAME!U8=0,"",MonthlyFAME!U8)
A7: =IF(MonthlyFAME!A9=0,"",MonthlyFAME!A9) -> 22006 | B7: =IF(MonthlyFAME!B9=0,"",MonthlyFAME!B9) | C7: =IF(MonthlyFAME!C9=0,"",MonthlyFAME!C9) -> 41.3 | D7: =IF(MonthlyFAME!D9=0,"",MonthlyFAME!D9) | E7: =IF(MonthlyFAME!F9=0,"",MonthlyFAME!F9) | F7: =IF(MonthlyFAME!G9=0,"",MonthlyFAME!G9) | G7: =IF(MonthlyFAME!H9=0,"",MonthlyFAME!H9) | H7: =IF(MonthlyFAME!I9=0,"",MonthlyFAME!I9) | I7: =IF(MonthlyFAME!J9=0,"",MonthlyFAME!J9) | K7: =IF(MonthlyFAME!L9=0,"",MonthlyFAME!L9) | L7: =IF(MonthlyFAME!M9=0,"",MonthlyFAME!M9) | M7: =IF(MonthlyFAME!N9=0,"",MonthlyFAME!N9) | N7: =IF(MonthlyFAME!O9=0,"",MonthlyFAME!O9) | O7: =IF(MonthlyFAME!P9=0,"",MonthlyFAME!P9) | P7: =IF(MonthlyFAME!Q9=0,"",MonthlyFAME!Q9) | Q7: =IF(MonthlyFAME!R9=0,"",MonthlyFAME!R9) | R7: =IF(MonthlyFAME!S9=0,"",MonthlyFAME!S9) | ... T7: =IF(MonthlyFAME!U9=0,"",MonthlyFAME!U9)
A8: =IF(MonthlyFAME!A10=0,"",MonthlyFAME!A10) -> 22036 | B8: =IF(MonthlyFAME!B10=0,"",MonthlyFAME!B10) | C8: =IF(MonthlyFAME!C10=0,"",MonthlyFAME!C10) -> 41.3 | D8: =IF(MonthlyFAME!D10=0,"",MonthlyFAME!D10) | E8: =IF(MonthlyFAME!F10=0,"",MonthlyFAME!F10) | F8: =IF(MonthlyFAME!G10=0,"",MonthlyFAME!G10) | G8: =IF(MonthlyFAME!H10=0,"",MonthlyFAME!H10) | H8: =IF(MonthlyFAME!I10=0,"",MonthlyFAME!I10) | I8: =IF(MonthlyFAME!J10=0,"",MonthlyFAME!J10) | K8: =IF(MonthlyFAME!L10=0,"",MonthlyFAME!L10) | L8: =IF(MonthlyFAME!M10=0,"",MonthlyFAME!M10) | M8: =IF(MonthlyFAME!N10=0,"",MonthlyFAME!N10) | N8: =IF(MonthlyFAME!O10=0,"",MonthlyFAME!O10) | O8: =IF(MonthlyFAME!P10=0,"",MonthlyFAME!P10) | P8: =IF(MonthlyFAME!Q10=0,"",MonthlyFAME!Q10) | Q8: =IF(MonthlyFAME!R10=0,"",MonthlyFAME!R10) | R8: =IF(MonthlyFAME!S10=0,"",MonthlyFAME!S10) | ... T8: =IF(MonthlyFAME!U10=0,"",MonthlyFAME!U10) | V8: Transform
A9: =IF(MonthlyFAME!A11=0,"",MonthlyFAME!A11) -> 22067 | B9: =IF(MonthlyFAME!B11=0,"",MonthlyFAME!B11) | C9: =IF(MonthlyFAME!C11=0,"",MonthlyFAME!C11) -> 41.3 | D9: =IF(MonthlyFAME!D11=0,"",MonthlyFAME!D11) | E9: =IF(MonthlyFAME!F11=0,"",MonthlyFAME!F11) | F9: =IF(MonthlyFAME!G11=0,"",MonthlyFAME!G11) | G9: =IF(MonthlyFAME!H11=0,"",MonthlyFAME!H11) | H9: =IF(MonthlyFAME!I11=0,"",MonthlyFAME!I11) | I9: =IF(MonthlyFAME!J11=0,"",MonthlyFAME!J11) | K9: =IF(MonthlyFAME!L11=0,"",MonthlyFAME!L11) | L9: =IF(MonthlyFAME!M11=0,"",MonthlyFAME!M11) | M9: =IF(MonthlyFAME!N11=0,"",MonthlyFAME!N11) | N9: =IF(MonthlyFAME!O11=0,"",MonthlyFAME!O11) | O9: =IF(MonthlyFAME!P11=0,"",MonthlyFAME!P11) | P9: =IF(MonthlyFAME!Q11=0,"",MonthlyFAME!Q11) | Q9: =IF(MonthlyFAME!R11=0,"",MonthlyFAME!R11) | R9: =IF(MonthlyFAME!S11=0,"",MonthlyFAME!S11) | ... T9: =IF(MonthlyFAME!U11=0,"",MonthlyFAME!U11) | V9: 0 | W9: no transform
A10: =IF(MonthlyFAME!A12=0,"",MonthlyFAME!A12) -> 22097 | B10: =IF(MonthlyFAME!B12=0,"",MonthlyFAME!B12) | C10: =IF(MonthlyFAME!C12=0,"",MonthlyFAME!C12) -> 41.3 | D10: =IF(MonthlyFAME!D12=0,"",MonthlyFAME!D12) | E10: =IF(MonthlyFAME!F12=0,"",MonthlyFAME!F12) | F10: =IF(MonthlyFAME!G12=0,"",MonthlyFAME!G12) | G10: =IF(MonthlyFAME!H12=0,"",MonthlyFAME!H12) | H10: =IF(MonthlyFAME!I12=0,"",MonthlyFAME!I12) | I10: =IF(MonthlyFAME!J12=0,"",MonthlyFAME!J12) | K10: =IF(MonthlyFAME!L12=0,"",MonthlyFAME!L12) | L10: =IF(MonthlyFAME!M12=0,"",MonthlyFAME!M12) | M10: =IF(MonthlyFAME!N12=0,"",MonthlyFAME!N12) | N10: =IF(MonthlyFAME!O12=0,"",MonthlyFAME!O12) | O10: =IF(MonthlyFAME!P12=0,"",MonthlyFAME!P12) | P10: =IF(MonthlyFAME!Q12=0,"",MonthlyFAME!Q12) | Q10: =IF(MonthlyFAME!R12=0,"",MonthlyFAME!R12) | R10: =IF(MonthlyFAME!S12=0,"",MonthlyFAME!S12) | ... T10: =IF(MonthlyFAME!U12=0,"",MonthlyFAME!U12) | V10: 1 | W10: log
A11: =IF(MonthlyFAME!A13=0,"",MonthlyFAME!A13) -> 22128 | B11: =IF(MonthlyFAME!B13=0,"",MonthlyFAME!B13) | C11: =IF(MonthlyFAME!C13=0,"",MonthlyFAME!C13) -> 41.3 | D11: =IF(MonthlyFAME!D13=0,"",MonthlyFAME!D13) | E11: =IF(MonthlyFAME!F13=0,"",MonthlyFAME!F13) | F11: =IF(MonthlyFAME!G13=0,"",MonthlyFAME!G13) | G11: =IF(MonthlyFAME!H13=0,"",MonthlyFAME!H13) | H11: =IF(MonthlyFAME!I13=0,"",MonthlyFAME!I13) | I11: =IF(MonthlyFAME!J13=0,"",MonthlyFAME!J13) | K11: =IF(MonthlyFAME!L13=0,"",MonthlyFAME!L13) | L11: =IF(MonthlyFAME!M13=0,"",MonthlyFAME!M13) | M11: =IF(MonthlyFAME!N13=0,"",MonthlyFAME!N13) | N11: =IF(MonthlyFAME!O13=0,"",MonthlyFAME!O13) | O11: =IF(MonthlyFAME!P13=0,"",MonthlyFAME!P13) | P11: =IF(MonthlyFAME!Q13=0,"",MonthlyFAME!Q13) | Q11: =IF(MonthlyFAME!R13=0,"",MonthlyFAME!R13) | R11: =IF(MonthlyFAME!S13=0,"",MonthlyFAME!S13) | ... T11: =IF(MonthlyFAME!U13=0,"",MonthlyFAME!U13) | V11: 2 | W11: first diff
A12: =IF(MonthlyFAME!A14=0,"",MonthlyFAME!A14) -> 22159 | B12: =IF(MonthlyFAME!B14=0,"",MonthlyFAME!B14) | C12: =IF(MonthlyFAME!C14=0,"",MonthlyFAME!C14) -> 41.4 | D12: =IF(MonthlyFAME!D14=0,"",MonthlyFAME!D14) | E12: =IF(MonthlyFAME!F14=0,"",MonthlyFAME!F14) | F12: =IF(MonthlyFAME!G14=0,"",MonthlyFAME!G14) | G12: =IF(MonthlyFAME!H14=0,"",MonthlyFAME!H14) | H12: =IF(MonthlyFAME!I14=0,"",MonthlyFAME!I14) | I12: =IF(MonthlyFAME!J14=0,"",MonthlyFAME!J14) | K12: =IF(MonthlyFAME!L14=0,"",MonthlyFAME!L14) | L12: =IF(MonthlyFAME!M14=0,"",MonthlyFAME!M14) | M12: =IF(MonthlyFAME!N14=0,"",MonthlyFAME!N14) | N12: =IF(MonthlyFAME!O14=0,"",MonthlyFAME!O14) | O12: =IF(MonthlyFAME!P14=0,"",MonthlyFAME!P14) | P12: =IF(MonthlyFAME!Q14=0,"",MonthlyFAME!Q14) | Q12: =IF(MonthlyFAME!R14=0,"",MonthlyFAME!R14) | R12: =IF(MonthlyFAME!S14=0,"",MonthlyFAME!S14) | ... T12: =IF(MonthlyFAME!U14=0,"",MonthlyFAME!U14) | V12: 3 | W12: log first diff
A13: =IF(MonthlyFAME!A15=0,"",MonthlyFAME!A15) -> 22189 | B13: =IF(MonthlyFAME!B15=0,"",MonthlyFAME!B15) | C13: =IF(MonthlyFAME!C15=0,"",MonthlyFAME!C15) -> 41.7 | D13: =IF(MonthlyFAME!D15=0,"",MonthlyFAME!D15) | E13: =IF(MonthlyFAME!F15=0,"",MonthlyFAME!F15) | F13: =IF(MonthlyFAME!G15=0,"",MonthlyFAME!G15) | G13: =IF(MonthlyFAME!H15=0,"",MonthlyFAME!H15) | H13: =IF(MonthlyFAME!I15=0,"",MonthlyFAME!I15) | I13: =IF(MonthlyFAME!J15=0,"",MonthlyFAME!J15) | K13: =IF(MonthlyFAME!L15=0,"",MonthlyFAME!L15) | L13: =IF(MonthlyFAME!M15=0,"",MonthlyFAME!M15) | M13: =IF(MonthlyFAME!N15=0,"",MonthlyFAME!N15) | N13: =IF(MonthlyFAME!O15=0,"",MonthlyFAME!O15) | O13: =IF(MonthlyFAME!P15=0,"",MonthlyFAME!P15) | P13: =IF(MonthlyFAME!Q15=0,"",MonthlyFAME!Q15) | Q13: =IF(MonthlyFAME!R15=0,"",MonthlyFAME!R15) | R13: =IF(MonthlyFAME!S15=0,"",MonthlyFAME!S15) | ... T13: =IF(MonthlyFAME!U15=0,"",MonthlyFAME!U15) | V13: 4 | W13: y-o-y log diff
A14: =IF(MonthlyFAME!A16=0,"",MonthlyFAME!A16) -> 22220 | B14: =IF(MonthlyFAME!B16=0,"",MonthlyFAME!B16) | C14: =IF(MonthlyFAME!C16=0,"",MonthlyFAME!C16) -> 41.9 | D14: =IF(MonthlyFAME!D16=0,"",MonthlyFAME!D16) | E14: =IF(MonthlyFAME!F16=0,"",MonthlyFAME!F16) | F14: =IF(MonthlyFAME!G16=0,"",MonthlyFAME!G16) | G14: =IF(MonthlyFAME!H16=0,"",MonthlyFAME!H16) | H14: =IF(MonthlyFAME!I16=0,"",MonthlyFAME!I16) | I14: =IF(MonthlyFAME!J16=0,"",MonthlyFAME!J16) | K14: =IF(MonthlyFAME!L16=0,"",MonthlyFAME!L16) | L14: =IF(MonthlyFAME!M16=0,"",MonthlyFAME!M16) | M14: =IF(MonthlyFAME!N16=0,"",MonthlyFAME!N16) | N14: =IF(MonthlyFAME!O16=0,"",MonthlyFAME!O16) | O14: =IF(MonthlyFAME!P16=0,"",MonthlyFAME!P16) | P14: =IF(MonthlyFAME!Q16=0,"",MonthlyFAME!Q16) | Q14: =IF(MonthlyFAME!R16=0,"",MonthlyFAME!R16) | R14: =IF(MonthlyFAME!S16=0,"",MonthlyFAME!S16) | ... T14: =IF(MonthlyFAME!U16=0,"",MonthlyFAME!U16)
A15: =IF(MonthlyFAME!A17=0,"",MonthlyFAME!A17) -> 22250 | B15: =IF(MonthlyFAME!B17=0,"",MonthlyFAME!B17) | C15: =IF(MonthlyFAME!C17=0,"",MonthlyFAME!C17) -> 41.9 | D15: =IF(MonthlyFAME!D17=0,"",MonthlyFAME!D17) | E15: =IF(MonthlyFAME!F17=0,"",MonthlyFAME!F17) | F15: =IF(MonthlyFAME!G17=0,"",MonthlyFAME!G17) | G15: =IF(MonthlyFAME!H17=0,"",MonthlyFAME!H17) | H15: =IF(MonthlyFAME!I17=0,"",MonthlyFAME!I17) | I15: =IF(MonthlyFAME!J17=0,"",MonthlyFAME!J17) | K15: =IF(MonthlyFAME!L17=0,"",MonthlyFAME!L17) | L15: =IF(MonthlyFAME!M17=0,"",MonthlyFAME!M17) | M15: =IF(MonthlyFAME!N17=0,"",MonthlyFAME!N17) | N15: =IF(MonthlyFAME!O17=0,"",MonthlyFAME!O17) | O15: =IF(MonthlyFAME!P17=0,"",MonthlyFAME!P17) | P15: =IF(MonthlyFAME!Q17=0,"",MonthlyFAME!Q17) | Q15: =IF(MonthlyFAME!R17=0,"",MonthlyFAME!R17) | R15: =IF(MonthlyFAME!S17=0,"",MonthlyFAME!S17) | ... T15: =IF(MonthlyFAME!U17=0,"",MonthlyFAME!U17)
A16: =IF(MonthlyFAME!A18=0,"",MonthlyFAME!A18) -> 22281 | B16: =IF(MonthlyFAME!B18=0,"",MonthlyFAME!B18) | C16: =IF(MonthlyFAME!C18=0,"",MonthlyFAME!C18) -> 41.7 | D16: =IF(MonthlyFAME!D18=0,"",MonthlyFAME!D18) | E16: =IF(MonthlyFAME!F18=0,"",MonthlyFAME!F18) | F16: =IF(MonthlyFAME!G18=0,"",MonthlyFAME!G18) | G16: =IF(MonthlyFAME!H18=0,"",MonthlyFAME!H18) | H16: =IF(MonthlyFAME!I18=0,"",MonthlyFAME!I18) | I16: =IF(MonthlyFAME!J18=0,"",MonthlyFAME!J18) | K16: =IF(MonthlyFAME!L18=0,"",MonthlyFAME!L18) | L16: =IF(MonthlyFAME!M18=0,"",MonthlyFAME!M18) | M16: =IF(MonthlyFAME!N18=0,"",MonthlyFAME!N18) | N16: =IF(MonthlyFAME!O18=0,"",MonthlyFAME!O18) | O16: =IF(MonthlyFAME!P18=0,"",MonthlyFAME!P18) | P16: =IF(MonthlyFAME!Q18=0,"",MonthlyFAME!Q18) | Q16: =IF(MonthlyFAME!R18=0,"",MonthlyFAME!R18) | R16: =IF(MonthlyFAME!S18=0,"",MonthlyFAME!S18) | ... T16: =IF(MonthlyFAME!U18=0,"",MonthlyFAME!U18)
A17: =IF(MonthlyFAME!A19=0,"",MonthlyFAME!A19) -> 22312 | B17: =IF(MonthlyFAME!B19=0,"",MonthlyFAME!B19) | C17: =IF(MonthlyFAME!C19=0,"",MonthlyFAME!C19) -> 41.3 | D17: =IF(MonthlyFAME!D19=0,"",MonthlyFAME!D19) | E17: =IF(MonthlyFAME!F19=0,"",MonthlyFAME!F19) | F17: =IF(MonthlyFAME!G19=0,"",MonthlyFAME!G19) | G17: =IF(MonthlyFAME!H19=0,"",MonthlyFAME!H19) | H17: =IF(MonthlyFAME!I19=0,"",MonthlyFAME!I19) | I17: =IF(MonthlyFAME!J19=0,"",MonthlyFAME!J19) | K17: =IF(MonthlyFAME!L19=0,"",MonthlyFAME!L19) | L17: =IF(MonthlyFAME!M19=0,"",MonthlyFAME!M19) | M17: =IF(MonthlyFAME!N19=0,"",MonthlyFAME!N19) | N17: =IF(MonthlyFAME!O19=0,"",MonthlyFAME!O19) | O17: =IF(MonthlyFAME!P19=0,"",MonthlyFAME!P19) | P17: =IF(MonthlyFAME!Q19=0,"",MonthlyFAME!Q19) | Q17: =IF(MonthlyFAME!R19=0,"",MonthlyFAME!R19) | R17: =IF(MonthlyFAME!S19=0,"",MonthlyFAME!S19) | ... T17: =IF(MonthlyFAME!U19=0,"",MonthlyFAME!U19)
A18: =IF(MonthlyFAME!A20=0,"",MonthlyFAME!A20) -> 22340 | B18: =IF(MonthlyFAME!B20=0,"",MonthlyFAME!B20) | C18: =IF(MonthlyFAME!C20=0,"",MonthlyFAME!C20) -> 41.1 | D18: =IF(MonthlyFAME!D20=0,"",MonthlyFAME!D20) | E18: =IF(MonthlyFAME!F20=0,"",MonthlyFAME!F20) | F18: =IF(MonthlyFAME!G20=0,"",MonthlyFAME!G20) | G18: =IF(MonthlyFAME!H20=0,"",MonthlyFAME!H20) | H18: =IF(MonthlyFAME!I20=0,"",MonthlyFAME!I20) | I18: =IF(MonthlyFAME!J20=0,"",MonthlyFAME!J20) | K18: =IF(MonthlyFAME!L20=0,"",MonthlyFAME!L20) | L18: =IF(MonthlyFAME!M20=0,"",MonthlyFAME!M20) | M18: =IF(MonthlyFAME!N20=0,"",MonthlyFAME!N20) | N18: =IF(MonthlyFAME!O20=0,"",MonthlyFAME!O20) | O18: =IF(MonthlyFAME!P20=0,"",MonthlyFAME!P20) | P18: =IF(MonthlyFAME!Q20=0,"",MonthlyFAME!Q20) | Q18: =IF(MonthlyFAME!R20=0,"",MonthlyFAME!R20) | R18: =IF(MonthlyFAME!S20=0,"",MonthlyFAME!S20) | ... T18: =IF(MonthlyFAME!U20=0,"",MonthlyFAME!U20)
A19: =IF(MonthlyFAME!A21=0,"",MonthlyFAME!A21) -> 22371 | B19: =IF(MonthlyFAME!B21=0,"",MonthlyFAME!B21) | C19: =IF(MonthlyFAME!C21=0,"",MonthlyFAME!C21) -> 41.3 | D19: =IF(MonthlyFAME!D21=0,"",MonthlyFAME!D21) | E19: =IF(MonthlyFAME!F21=0,"",MonthlyFAME!F21) | F19: =IF(MonthlyFAME!G21=0,"",MonthlyFAME!G21) | G19: =IF(MonthlyFAME!H21=0,"",MonthlyFAME!H21) | H19: =IF(MonthlyFAME!I21=0,"",MonthlyFAME!I21) | I19: =IF(MonthlyFAME!J21=0,"",MonthlyFAME!J21) | K19: =IF(MonthlyFAME!L21=0,"",MonthlyFAME!L21) | L19: =IF(MonthlyFAME!M21=0,"",MonthlyFAME!M21) | M19: =IF(MonthlyFAME!N21=0,"",MonthlyFAME!N21) | N19: =IF(MonthlyFAME!O21=0,"",MonthlyFAME!O21) | O19: =IF(MonthlyFAME!P21=0,"",MonthlyFAME!P21) | P19: =IF(MonthlyFAME!Q21=0,"",MonthlyFAME!Q21) | Q19: =IF(MonthlyFAME!R21=0,"",MonthlyFAME!R21) | R19: =IF(MonthlyFAME!S21=0,"",MonthlyFAME!S21) | ... T19: =IF(MonthlyFAME!U21=0,"",MonthlyFAME!U21)
A20: =IF(MonthlyFAME!A22=0,"",MonthlyFAME!A22) -> 22401 | B20: =IF(MonthlyFAME!B22=0,"",MonthlyFAME!B22) | C20: =IF(MonthlyFAME!C22=0,"",MonthlyFAME!C22) -> 41.7 | D20: =IF(MonthlyFAME!D22=0,"",MonthlyFAME!D22) | E20: =IF(MonthlyFAME!F22=0,"",MonthlyFAME!F22) | F20: =IF(MonthlyFAME!G22=0,"",MonthlyFAME!G22) | G20: =IF(MonthlyFAME!H22=0,"",MonthlyFAME!H22) | H20: =IF(MonthlyFAME!I22=0,"",MonthlyFAME!I22) | I20: =IF(MonthlyFAME!J22=0,"",MonthlyFAME!J22) | K20: =IF(MonthlyFAME!L22=0,"",MonthlyFAME!L22) | L20: =IF(MonthlyFAME!M22=0,"",MonthlyFAME!M22) | M20: =IF(MonthlyFAME!N22=0,"",MonthlyFAME!N22) | N20: =IF(MonthlyFAME!O22=0,"",MonthlyFAME!O22) | O20: =IF(MonthlyFAME!P22=0,"",MonthlyFAME!P22) | P20: =IF(MonthlyFAME!Q22=0,"",MonthlyFAME!Q22) | Q20: =IF(MonthlyFAME!R22=0,"",MonthlyFAME!R22) | R20: =IF(MonthlyFAME!S22=0,"",MonthlyFAME!S22) | ... T20: =IF(MonthlyFAME!U22=0,"",MonthlyFAME!U22)
A21: =IF(MonthlyFAME!A23=0,"",MonthlyFAME!A23) -> 22432 | B21: =IF(MonthlyFAME!B23=0,"",MonthlyFAME!B23) | C21: =IF(MonthlyFAME!C23=0,"",MonthlyFAME!C23) -> 42 | D21: =IF(MonthlyFAME!D23=0,"",MonthlyFAME!D23) | E21: =IF(MonthlyFAME!F23=0,"",MonthlyFAME!F23) | F21: =IF(MonthlyFAME!G23=0,"",MonthlyFAME!G23) | G21: =IF(MonthlyFAME!H23=0,"",MonthlyFAME!H23) | H21: =IF(MonthlyFAME!I23=0,"",MonthlyFAME!I23) | I21: =IF(MonthlyFAME!J23=0,"",MonthlyFAME!J23) | K21: =IF(MonthlyFAME!L23=0,"",MonthlyFAME!L23) | L21: =IF(MonthlyFAME!M23=0,"",MonthlyFAME!M23) | M21: =IF(MonthlyFAME!N23=0,"",MonthlyFAME!N23) | N21: =IF(MonthlyFAME!O23=0,"",MonthlyFAME!O23) | O21: =IF(MonthlyFAME!P23=0,"",MonthlyFAME!P23) | P21: =IF(MonthlyFAME!Q23=0,"",MonthlyFAME!Q23) | Q21: =IF(MonthlyFAME!R23=0,"",MonthlyFAME!R23) | R21: =IF(MonthlyFAME!S23=0,"",MonthlyFAME!S23) | ... T21: =IF(MonthlyFAME!U23=0,"",MonthlyFAME!U23)
A22: =IF(MonthlyFAME!A24=0,"",MonthlyFAME!A24) -> 22462 | B22: =IF(MonthlyFAME!B24=0,"",MonthlyFAME!B24) | C22: =IF(MonthlyFAME!C24=0,"",MonthlyFAME!C24) -> 42.1 | D22: =IF(MonthlyFAME!D24=0,"",MonthlyFAME!D24) | E22: =IF(MonthlyFAME!F24=0,"",MonthlyFAME!F24) | F22: =IF(MonthlyFAME!G24=0,"",MonthlyFAME!G24) | G22: =IF(MonthlyFAME!H24=0,"",MonthlyFAME!H24) | H22: =IF(MonthlyFAME!I24=0,"",MonthlyFAME!I24) | I22: =IF(MonthlyFAME!J24=0,"",MonthlyFAME!J24) | K22: =IF(MonthlyFAME!L24=0,"",MonthlyFAME!L24) | L22: =IF(MonthlyFAME!M24=0,"",MonthlyFAME!M24) | M22: =IF(MonthlyFAME!N24=0,"",MonthlyFAME!N24) | N22: =IF(MonthlyFAME!O24=0,"",MonthlyFAME!O24) | O22: =IF(MonthlyFAME!P24=0,"",MonthlyFAME!P24) | P22: =IF(MonthlyFAME!Q24=0,"",MonthlyFAME!Q24) | Q22: =IF(MonthlyFAME!R24=0,"",MonthlyFAME!R24) | R22: =IF(MonthlyFAME!S24=0,"",MonthlyFAME!S24) | ... T22: =IF(MonthlyFAME!U24=0,"",MonthlyFAME!U24)
A23: =IF(MonthlyFAME!A25=0,"",MonthlyFAME!A25) -> 22493 | B23: =IF(MonthlyFAME!B25=0,"",MonthlyFAME!B25) | C23: =IF(MonthlyFAME!C25=0,"",MonthlyFAME!C25) -> 41.9 | D23: =IF(MonthlyFAME!D25=0,"",MonthlyFAME!D25) | E23: =IF(MonthlyFAME!F25=0,"",MonthlyFAME!F25) | F23: =IF(MonthlyFAME!G25=0,"",MonthlyFAME!G25) | G23: =IF(MonthlyFAME!H25=0,"",MonthlyFAME!H25) | H23: =IF(MonthlyFAME!I25=0,"",MonthlyFAME!I25) | I23: =IF(MonthlyFAME!J25=0,"",MonthlyFAME!J25) | K23: =IF(MonthlyFAME!L25=0,"",MonthlyFAME!L25) | L23: =IF(MonthlyFAME!M25=0,"",MonthlyFAME!M25) | M23: =IF(MonthlyFAME!N25=0,"",MonthlyFAME!N25) | N23: =IF(MonthlyFAME!O25=0,"",MonthlyFAME!O25) | O23: =IF(MonthlyFAME!P25=0,"",MonthlyFAME!P25) | P23: =IF(MonthlyFAME!Q25=0,"",MonthlyFAME!Q25) | Q23: =IF(MonthlyFAME!R25=0,"",MonthlyFAME!R25) | R23: =IF(MonthlyFAME!S25=0,"",MonthlyFAME!S25) | ... T23: =IF(MonthlyFAME!U25=0,"",MonthlyFAME!U25)
A24: =IF(MonthlyFAME!A26=0,"",MonthlyFAME!A26) -> 22524 | B24: =IF(MonthlyFAME!B26=0,"",MonthlyFAME!B26) | C24: =IF(MonthlyFAME!C26=0,"",MonthlyFAME!C26) -> 41.7 | D24: =IF(MonthlyFAME!D26=0,"",MonthlyFAME!D26) | E24: =IF(MonthlyFAME!F26=0,"",MonthlyFAME!F26) | F24: =IF(MonthlyFAME!G26=0,"",MonthlyFAME!G26) | G24: =IF(MonthlyFAME!H26=0,"",MonthlyFAME!H26) | H24: =IF(MonthlyFAME!I26=0,"",MonthlyFAME!I26) | I24: =IF(MonthlyFAME!J26=0,"",MonthlyFAME!J26) | K24: =IF(MonthlyFAME!L26=0,"",MonthlyFAME!L26) | L24: =IF(MonthlyFAME!M26=0,"",MonthlyFAME!M26) | M24: =IF(MonthlyFAME!N26=0,"",MonthlyFAME!N26) | N24: =IF(MonthlyFAME!O26=0,"",MonthlyFAME!O26) | O24: =IF(MonthlyFAME!P26=0,"",MonthlyFAME!P26) | P24: =IF(MonthlyFAME!Q26=0,"",MonthlyFAME!Q26) | Q24: =IF(MonthlyFAME!R26=0,"",MonthlyFAME!R26) | R24: =IF(MonthlyFAME!S26=0,"",MonthlyFAME!S26) | ... T24: =IF(MonthlyFAME!U26=0,"",MonthlyFAME!U26)
A25: =IF(MonthlyFAME!A27=0,"",MonthlyFAME!A27) -> 22554 | B25: =IF(MonthlyFAME!B27=0,"",MonthlyFAME!B27) | C25: =IF(MonthlyFAME!C27=0,"",MonthlyFAME!C27) -> 41.6 | D25: =IF(MonthlyFAME!D27=0,"",MonthlyFAME!D27) | E25: =IF(MonthlyFAME!F27=0,"",MonthlyFAME!F27) | F25: =IF(MonthlyFAME!G27=0,"",MonthlyFAME!G27) | G25: =IF(MonthlyFAME!H27=0,"",MonthlyFAME!H27) | H25: =IF(MonthlyFAME!I27=0,"",MonthlyFAME!I27) | I25: =IF(MonthlyFAME!J27=0,"",MonthlyFAME!J27) | K25: =IF(MonthlyFAME!L27=0,"",MonthlyFAME!L27) | L25: =IF(MonthlyFAME!M27=0,"",MonthlyFAME!M27) | M25: =IF(MonthlyFAME!N27=0,"",MonthlyFAME!N27) | N25: =IF(MonthlyFAME!O27=0,"",MonthlyFAME!O27) | O25: =IF(MonthlyFAME!P27=0,"",MonthlyFAME!P27) | P25: =IF(MonthlyFAME!Q27=0,"",MonthlyFAME!Q27) | Q25: =IF(MonthlyFAME!R27=0,"",MonthlyFAME!R27) | R25: =IF(MonthlyFAME!S27=0,"",MonthlyFAME!S27) | ... T25: =IF(MonthlyFAME!U27=0,"",MonthlyFAME!U27)
... A415: =IF(MonthlyFAME!A417=0,"",MonthlyFAME!A417) -> 34424 | B415: =IF(MonthlyFAME!B417=0,"",MonthlyFAME!B417) | C415: =IF(MonthlyFAME!C417=0,"",MonthlyFAME!C417) -> 76.8 | D415: =IF(MonthlyFAME!D417=0,"",MonthlyFAME!D417) | E415: =IF(MonthlyFAME!F417=0,"",MonthlyFAME!F417) -> 10671 | F415: =IF(MonthlyFAME!G417=0,"",MonthlyFAME!G417) -> 11675 | G415: =IF(MonthlyFAME!H417=0,"",MonthlyFAME!H417) -> 9.9454172 | H415: =IF(MonthlyFAME!I417=0,"",MonthlyFAME!I417) -> 25408 | I415: =IF(MonthlyFAME!J417=0,"",MonthlyFAME!J417) -> 837.1 | K415: =IF(MonthlyFAME!L417=0,"",MonthlyFAME!L417) -> 241.03294 | L415: =IF(MonthlyFAME!M417=0,"",MonthlyFAME!M417) -> 2712 | M415: =IF(MonthlyFAME!N417=0,"",MonthlyFAME!N417) | N415: =IF(MonthlyFAME!O417=0,"",MonthlyFAME!O417) | O415: =IF(MonthlyFAME!P417=0,"",MonthlyFAME!P417) | P415: =IF(MonthlyFAME!Q417=0,"",MonthlyFAME!Q417) | Q415: =IF(MonthlyFAME!R417=0,"",MonthlyFAME!R417) | R415: =IF(MonthlyFAME!S417=0,"",MonthlyFAME!S417) | ... T415: =IF(MonthlyFAME!U417=0,"",MonthlyFAME!U417) -> 13.892174
A416: =IF(MonthlyFAME!A418=0,"",MonthlyFAME!A418) -> 34454 | B416: =IF(MonthlyFAME!B418=0,"",MonthlyFAME!B418) | C416: =IF(MonthlyFAME!C418=0,"",MonthlyFAME!C418) -> 77.8 | E416: =IF(MonthlyFAME!F418=0,"",MonthlyFAME!F418) -> 10655 | F416: =IF(MonthlyFAME!G418=0,"",MonthlyFAME!G418) -> 11465 | G416: =IF(MonthlyFAME!H418=0,"",MonthlyFAME!H418) -> 9.8121899 | H416: =IF(MonthlyFAME!I418=0,"",MonthlyFAME!I418) -> 25451 | I416: =IF(MonthlyFAME!J418=0,"",MonthlyFAME!J418) -> 842.1 | K416: =IF(MonthlyFAME!L418=0,"",MonthlyFAME!L418) -> 240.69583 | L416: =IF(MonthlyFAME!M418=0,"",MonthlyFAME!M418) -> 2676.3 | M416: =IF(MonthlyFAME!N418=0,"",MonthlyFAME!N418) | N416: =IF(MonthlyFAME!O418=0,"",MonthlyFAME!O418) | O416: =IF(MonthlyFAME!P418=0,"",MonthlyFAME!P418) | P416: =IF(MonthlyFAME!Q418=0,"",MonthlyFAME!Q418) | Q416: =IF(MonthlyFAME!R418=0,"",MonthlyFAME!R418) | R416: =IF(MonthlyFAME!S418=0,"",MonthlyFAME!S418) | ... T416: =IF(MonthlyFAME!U418=0,"",MonthlyFAME!U418) -> 15.095238
A417: =IF(MonthlyFAME!A419=0,"",MonthlyFAME!A419) -> 34485 | B417: =IF(MonthlyFAME!B419=0,"",MonthlyFAME!B419) | C417: =IF(MonthlyFAME!C419=0,"",MonthlyFAME!C419) -> 78.8 | E417: =IF(MonthlyFAME!F419=0,"",MonthlyFAME!F419) -> 10468 | F417: =IF(MonthlyFAME!G419=0,"",MonthlyFAME!G419) -> 11690 | G417: =IF(MonthlyFAME!H419=0,"",MonthlyFAME!H419) -> 9.7500443 | H417: =IF(MonthlyFAME!I419=0,"",MonthlyFAME!I419) -> 25455 | I417: =IF(MonthlyFAME!J419=0,"",MonthlyFAME!J419) -> 840.4 | K417: =IF(MonthlyFAME!L419=0,"",MonthlyFAME!L419) -> 243.25943 | L417: =IF(MonthlyFAME!M419=0,"",MonthlyFAME!M419) -> 2652.6 | M417: =IF(MonthlyFAME!N419=0,"",MonthlyFAME!N419) | N417: =IF(MonthlyFAME!O419=0,"",MonthlyFAME!O419) | O417: =IF(MonthlyFAME!P419=0,"",MonthlyFAME!P419) | P417: =IF(MonthlyFAME!Q419=0,"",MonthlyFAME!Q419) | Q417: =IF(MonthlyFAME!R419=0,"",MonthlyFAME!R419) | R417: =IF(MonthlyFAME!S419=0,"",MonthlyFAME!S419) | ... T417: =IF(MonthlyFAME!U419=0,"",MonthlyFAME!U419) -> 16.204545
A418: =IF(MonthlyFAME!A420=0,"",MonthlyFAME!A420) -> 34515 | B418: =IF(MonthlyFAME!B420=0,"",MonthlyFAME!B420) | C418: =IF(MonthlyFAME!C420=0,"",MonthlyFAME!C420) -> 77.9 | E418: =IF(MonthlyFAME!F420=0,"",MonthlyFAME!F420) -> 11118 | F418: =IF(MonthlyFAME!G420=0,"",MonthlyFAME!G420) -> 11560 | G418: =IF(MonthlyFAME!H420=0,"",MonthlyFAME!H420) -> 9.7066023 | H418: =IF(MonthlyFAME!I420=0,"",MonthlyFAME!I420) -> 25451 | I418: =IF(MonthlyFAME!J420=0,"",MonthlyFAME!J420) -> 839.2 | K418: =IF(MonthlyFAME!L420=0,"",MonthlyFAME!L420) -> 243.94549 | L418: =IF(MonthlyFAME!M420=0,"",MonthlyFAME!M420) -> 2624.9 | M418: =IF(MonthlyFAME!N420=0,"",MonthlyFAME!N420) | N418: =IF(MonthlyFAME!O420=0,"",MonthlyFAME!O420) | O418: =IF(MonthlyFAME!P420=0,"",MonthlyFAME!P420) | P418: =IF(MonthlyFAME!Q420=0,"",MonthlyFAME!Q420) | Q418: =IF(MonthlyFAME!R420=0,"",MonthlyFAME!R420) | R418: =IF(MonthlyFAME!S420=0,"",MonthlyFAME!S420) | ... T418: =IF(MonthlyFAME!U420=0,"",MonthlyFAME!U420) -> 16.782727
A419: =IF(MonthlyFAME!A421=0,"",MonthlyFAME!A421) -> 34546 | B419: =IF(MonthlyFAME!B421=0,"",MonthlyFAME!B421) | C419: =IF(MonthlyFAME!C421=0,"",MonthlyFAME!C421) -> 78.3 | E419: =IF(MonthlyFAME!F421=0,"",MonthlyFAME!F421) -> 10652 | F419: =IF(MonthlyFAME!G421=0,"",MonthlyFAME!G421) -> 11514 | G419: =IF(MonthlyFAME!H421=0,"",MonthlyFAME!H421) -> 9.5850608 | H419: =IF(MonthlyFAME!I421=0,"",MonthlyFAME!I421) -> 25516 | I419: =IF(MonthlyFAME!J421=0,"",MonthlyFAME!J421) -> 841.1 | K419: =IF(MonthlyFAME!L421=0,"",MonthlyFAME!L421) -> 244.77739 | L419: =IF(MonthlyFAME!M421=0,"",MonthlyFAME!M421) -> 2593.5 | M419: =IF(MonthlyFAME!N421=0,"",MonthlyFAME!N421) | N419: =IF(MonthlyFAME!O421=0,"",MonthlyFAME!O421) | O419: =IF(MonthlyFAME!P421=0,"",MonthlyFAME!P421) | P419: =IF(MonthlyFAME!Q421=0,"",MonthlyFAME!Q421) | Q419: =IF(MonthlyFAME!R421=0,"",MonthlyFAME!R421) | R419: =IF(MonthlyFAME!S421=0,"",MonthlyFAME!S421) | ... T419: =IF(MonthlyFAME!U421=0,"",MonthlyFAME!U421) -> 17.604762
A420: =IF(MonthlyFAME!A422=0,"",MonthlyFAME!A422) -> 34577 | B420: =IF(MonthlyFAME!B422=0,"",MonthlyFAME!B422) | C420: =IF(MonthlyFAME!C422=0,"",MonthlyFAME!C422) -> 78.6 | E420: =IF(MonthlyFAME!F422=0,"",MonthlyFAME!F422) -> 11152 | F420: =IF(MonthlyFAME!G422=0,"",MonthlyFAME!G422) -> 11317 | G420: =IF(MonthlyFAME!H422=0,"",MonthlyFAME!H422) -> 9.5398469 | H420: =IF(MonthlyFAME!I422=0,"",MonthlyFAME!I422) -> 25517 | I420: =IF(MonthlyFAME!J422=0,"",MonthlyFAME!J422) -> 843.9 | K420: =IF(MonthlyFAME!L422=0,"",MonthlyFAME!L422) -> 245.57077 | L420: =IF(MonthlyFAME!M422=0,"",MonthlyFAME!M422) -> 2553.2 | M420: =IF(MonthlyFAME!N422=0,"",MonthlyFAME!N422) | N420: =IF(MonthlyFAME!O422=0,"",MonthlyFAME!O422) | O420: =IF(MonthlyFAME!P422=0,"",MonthlyFAME!P422) | P420: =IF(MonthlyFAME!Q422=0,"",MonthlyFAME!Q422) | Q420: =IF(MonthlyFAME!R422=0,"",MonthlyFAME!R422) | R420: =IF(MonthlyFAME!S422=0,"",MonthlyFAME!S422) | ... T420: =IF(MonthlyFAME!U422=0,"",MonthlyFAME!U422) -> 16.727826
A421: =IF(MonthlyFAME!A423=0,"",MonthlyFAME!A423) -> 34607 | B421: =IF(MonthlyFAME!B423=0,"",MonthlyFAME!B423) | C421: =IF(MonthlyFAME!C423=0,"",MonthlyFAME!C423) -> 79.3 | E421: =IF(MonthlyFAME!F423=0,"",MonthlyFAME!F423) -> 11026 | F421: =IF(MonthlyFAME!G423=0,"",MonthlyFAME!G423) -> 11575 | G421: =IF(MonthlyFAME!H423=0,"",MonthlyFAME!H423) -> 9.3588198 | H421: =IF(MonthlyFAME!I423=0,"",MonthlyFAME!I423) -> 25559 | I421: =IF(MonthlyFAME!J423=0,"",MonthlyFAME!J423) -> 846.3 | K421: =IF(MonthlyFAME!L423=0,"",MonthlyFAME!L423) -> 245.77298 | L421: =IF(MonthlyFAME!M423=0,"",MonthlyFAME!M423) -> 2524.5 | M421: =IF(MonthlyFAME!N423=0,"",MonthlyFAME!N423) | N421: =IF(MonthlyFAME!O423=0,"",MonthlyFAME!O423) | O421: =IF(MonthlyFAME!P423=0,"",MonthlyFAME!P423) | P421: =IF(MonthlyFAME!Q423=0,"",MonthlyFAME!Q423) | Q421: =IF(MonthlyFAME!R423=0,"",MonthlyFAME!R423) | R421: =IF(MonthlyFAME!S423=0,"",MonthlyFAME!S423) | ... T421: =IF(MonthlyFAME!U423=0,"",MonthlyFAME!U423) -> 15.83
A422: =IF(MonthlyFAME!A424=0,"",MonthlyFAME!A424) -> 34638 | B422: =IF(MonthlyFAME!B424=0,"",MonthlyFAME!B424) | C422: =IF(MonthlyFAME!C424=0,"",MonthlyFAME!C424) -> 79.5 | E422: =IF(MonthlyFAME!F424=0,"",MonthlyFAME!F424) -> 11143 | F422: =IF(MonthlyFAME!G424=0,"",MonthlyFAME!G424) -> 11749 | G422: =IF(MonthlyFAME!H424=0,"",MonthlyFAME!H424) -> 9.2584046 | H422: =IF(MonthlyFAME!I424=0,"",MonthlyFAME!I424) -> 25561 | I422: =IF(MonthlyFAME!J424=0,"",MonthlyFAME!J424) -> 846.4 | K422: =IF(MonthlyFAME!L424=0,"",MonthlyFAME!L424) -> 247.28118 | L422: =IF(MonthlyFAME!M424=0,"",MonthlyFAME!M424) -> 2484.9 | M422: =IF(MonthlyFAME!N424=0,"",MonthlyFAME!N424) | N422: =IF(MonthlyFAME!O424=0,"",MonthlyFAME!O424) | O422: =IF(MonthlyFAME!P424=0,"",MonthlyFAME!P424) | P422: =IF(MonthlyFAME!Q424=0,"",MonthlyFAME!Q424) | Q422: =IF(MonthlyFAME!R424=0,"",MonthlyFAME!R424) | R422: =IF(MonthlyFAME!S424=0,"",MonthlyFAME!S424) | ... T422: =IF(MonthlyFAME!U424=0,"",MonthlyFAME!U424) -> 16.457143
A423: =IF(MonthlyFAME!A425=0,"",MonthlyFAME!A425) -> 34668 | B423: =IF(MonthlyFAME!B425=0,"",MonthlyFAME!B425) | C423: =IF(MonthlyFAME!C425=0,"",MonthlyFAME!C425) -> 79.4 | E423: =IF(MonthlyFAME!F425=0,"",MonthlyFAME!F425) -> 11788 | F423: =IF(MonthlyFAME!G425=0,"",MonthlyFAME!G425) -> 12016 | G423: =IF(MonthlyFAME!H425=0,"",MonthlyFAME!H425) -> 9.079929 | H423: =IF(MonthlyFAME!I425=0,"",MonthlyFAME!I425) -> 25594 | I423: =IF(MonthlyFAME!J425=0,"",MonthlyFAME!J425) -> 847.1 | K423: =IF(MonthlyFAME!L425=0,"",MonthlyFAME!L425) -> 247.67618 | L423: =IF(MonthlyFAME!M425=0,"",MonthlyFAME!M425) -> 2453.5 | M423: =IF(MonthlyFAME!N425=0,"",MonthlyFAME!N425) | N423: =IF(MonthlyFAME!O425=0,"",MonthlyFAME!O425) | O423: =IF(MonthlyFAME!P425=0,"",MonthlyFAME!P425) | P423: =IF(MonthlyFAME!Q425=0,"",MonthlyFAME!Q425) | Q423: =IF(MonthlyFAME!R425=0,"",MonthlyFAME!R425) | R423: =IF(MonthlyFAME!S425=0,"",MonthlyFAME!S425) | ... T423: =IF(MonthlyFAME!U425=0,"",MonthlyFAME!U425) -> 17.217273
A424: =IF(MonthlyFAME!A426=0,"",MonthlyFAME!A426) -> 34699 | B424: =IF(MonthlyFAME!B426=0,"",MonthlyFAME!B426) | C424: =IF(MonthlyFAME!C426=0,"",MonthlyFAME!C426) -> 80.2 | E424: =IF(MonthlyFAME!F426=0,"",MonthlyFAME!F426) -> 11272 | F424: =IF(MonthlyFAME!G426=0,"",MonthlyFAME!G426) -> 12228 | G424: =IF(MonthlyFAME!H426=0,"",MonthlyFAME!H426) -> 8.9648306 | H424: =IF(MonthlyFAME!I426=0,"",MonthlyFAME!I426) -> 25600 | I424: =IF(MonthlyFAME!J426=0,"",MonthlyFAME!J426) -> 853 | K424: =IF(MonthlyFAME!L426=0,"",MonthlyFAME!L426) -> 249.1837 | L424: =IF(MonthlyFAME!M426=0,"",MonthlyFAME!M426) -> 2407.4 | M424: =IF(MonthlyFAME!N426=0,"",MonthlyFAME!N426) | N424: =IF(MonthlyFAME!O426=0,"",MonthlyFAME!O426) | O424: =IF(MonthlyFAME!P426=0,"",MonthlyFAME!P426) | P424: =IF(MonthlyFAME!Q426=0,"",MonthlyFAME!Q426) | Q424: =IF(MonthlyFAME!R426=0,"",MonthlyFAME!R426) | R424: =IF(MonthlyFAME!S426=0,"",MonthlyFAME!S426) | ... T424: =IF(MonthlyFAME!U426=0,"",MonthlyFAME!U426) -> 15.855455
A425: =IF(MonthlyFAME!A427=0,"",MonthlyFAME!A427) -> 34730 | B425: =IF(MonthlyFAME!B427=0,"",MonthlyFAME!B427) | C425: =IF(MonthlyFAME!C427=0,"",MonthlyFAME!C427) -> 78.8 | E425: =IF(MonthlyFAME!F427=0,"",MonthlyFAME!F427) -> 11589 | F425: =IF(MonthlyFAME!G427=0,"",MonthlyFAME!G427) -> 11737 | G425: =IF(MonthlyFAME!H427=0,"",MonthlyFAME!H427) -> 8.8924501 | H425: =IF(MonthlyFAME!I427=0,"",MonthlyFAME!I427) -> 25583 | I425: =IF(MonthlyFAME!J427=0,"",MonthlyFAME!J427) -> 854.5 | K425: =IF(MonthlyFAME!L427=0,"",MonthlyFAME!L427) -> 249.23629 | L425: =IF(MonthlyFAME!M427=0,"",MonthlyFAME!M427) -> 2387.3 | M425: =IF(MonthlyFAME!N427=0,"",MonthlyFAME!N427) | N425: =IF(MonthlyFAME!O427=0,"",MonthlyFAME!O427) | O425: =IF(MonthlyFAME!P427=0,"",MonthlyFAME!P427) | P425: =IF(MonthlyFAME!Q427=0,"",MonthlyFAME!Q427) | Q425: =IF(MonthlyFAME!R427=0,"",MonthlyFAME!R427) | R425: =IF(MonthlyFAME!S427=0,"",MonthlyFAME!S427) | ... T425: =IF(MonthlyFAME!U427=0,"",MonthlyFAME!U427) -> 16.569545
A426: =IF(MonthlyFAME!A428=0,"",MonthlyFAME!A428) -> 34758 | B426: =IF(MonthlyFAME!B428=0,"",MonthlyFAME!B428) | C426: =IF(MonthlyFAME!C428=0,"",MonthlyFAME!C428) -> 78.9 | E426: =IF(MonthlyFAME!F428=0,"",MonthlyFAME!F428) -> 11657 | F426: =IF(MonthlyFAME!G428=0,"",MonthlyFAME!G428) -> 11794 | G426: =IF(MonthlyFAME!H428=0,"",MonthlyFAME!H428) -> 8.8718277 | H426: =IF(MonthlyFAME!I428=0,"",MonthlyFAME!I428) -> 25638 | I426: =IF(MonthlyFAME!J428=0,"",MonthlyFAME!J428) -> 853.5 | K426: =IF(MonthlyFAME!L428=0,"",MonthlyFAME!L428) -> 250.12922 | L426: =IF(MonthlyFAME!M428=0,"",MonthlyFAME!M428) -> 2358.6 | M426: =IF(MonthlyFAME!N428=0,"",MonthlyFAME!N428) | N426: =IF(MonthlyFAME!O428=0,"",MonthlyFAME!O428) | O426: =IF(MonthlyFAME!P428=0,"",MonthlyFAME!P428) | P426: =IF(MonthlyFAME!Q428=0,"",MonthlyFAME!Q428) | Q426: =IF(MonthlyFAME!R428=0,"",MonthlyFAME!R428) | R426: =IF(MonthlyFAME!S428=0,"",MonthlyFAME!S428) | ... T426: =IF(MonthlyFAME!U428=0,"",MonthlyFAME!U428) -> 17.1025
A427: =IF(MonthlyFAME!A429=0,"",MonthlyFAME!A429) -> 34789 | B427: =IF(MonthlyFAME!B429=0,"",MonthlyFAME!B429) | C427: =IF(MonthlyFAME!C429=0,"",MonthlyFAME!C429) -> 79.2 | E427: =IF(MonthlyFAME!F429=0,"",MonthlyFAME!F429) -> 12032 | F427: =IF(MonthlyFAME!G429=0,"",MonthlyFAME!G429) -> 12036 | G427: =IF(MonthlyFAME!H429=0,"",MonthlyFAME!H429) -> 8.8649838 | H427: =IF(MonthlyFAME!I429=0,"",MonthlyFAME!I429) -> 25670 | I427: =IF(MonthlyFAME!J429=0,"",MonthlyFAME!J429) -> 852.4 | K427: =IF(MonthlyFAME!L429=0,"",MonthlyFAME!L429) -> 250.99827 | L427: =IF(MonthlyFAME!M429=0,"",MonthlyFAME!M429) -> 2341.9 | M427: =IF(MonthlyFAME!N429=0,"",MonthlyFAME!N429) | N427: =IF(MonthlyFAME!O429=0,"",MonthlyFAME!O429) | O427: =IF(MonthlyFAME!P429=0,"",MonthlyFAME!P429) | P427: =IF(MonthlyFAME!Q429=0,"",MonthlyFAME!Q429) | Q427: =IF(MonthlyFAME!R429=0,"",MonthlyFAME!R429) | R427: =IF(MonthlyFAME!S429=0,"",MonthlyFAME!S429) | ... T427: =IF(MonthlyFAME!U429=0,"",MonthlyFAME!U429) -> 17.002609
... A448: =IF(MonthlyFAME!A450=0,"",MonthlyFAME!A450) -> 35430 | B448: =IF(MonthlyFAME!B450=0,"",MonthlyFAME!B450) | C448: =IF(MonthlyFAME!C450=0,"",MonthlyFAME!C450) -> 81.8 | E448: =IF(MonthlyFAME!F450=0,"",MonthlyFAME!F450) -> 12970 | F448: =IF(MonthlyFAME!G450=0,"",MonthlyFAME!G450) -> 13792 | G448: =IF(MonthlyFAME!H450=0,"",MonthlyFAME!H450) -> 7.8411369 | H448: =IF(MonthlyFAME!I450=0,"",MonthlyFAME!I450) -> 26198 | I448: =IF(MonthlyFAME!J450=0,"",MonthlyFAME!J450) -> 866.1 | K448: =IF(MonthlyFAME!L450=0,"",MonthlyFAME!L450) -> 267.10557 | L448: =IF(MonthlyFAME!M450=0,"",MonthlyFAME!M450) -> 1872.1 | M448: =IF(MonthlyFAME!N450=0,"",MonthlyFAME!N450) | N448: =IF(MonthlyFAME!O450=0,"",MonthlyFAME!O450) | O448: =IF(MonthlyFAME!P450=0,"",MonthlyFAME!P450) | P448: =IF(MonthlyFAME!Q450=0,"",MonthlyFAME!Q450) | Q448: =IF(MonthlyFAME!R450=0,"",MonthlyFAME!R450) | R448: =IF(MonthlyFAME!S450=0,"",MonthlyFAME!S450) | ... T448: =IF(MonthlyFAME!U450=0,"",MonthlyFAME!U450) -> 23.823182
A449: =IF(MonthlyFAME!A451=0,"",MonthlyFAME!A451) -> 35461 | B449: =IF(MonthlyFAME!B451=0,"",MonthlyFAME!B451) -> 63.3 | C449: =IF(MonthlyFAME!C451=0,"",MonthlyFAME!C451) -> 81.8 | D449: =IF(MonthlyFAME!D451=0,"",MonthlyFAME!D451) -> 58.9698 | E449: =IF(MonthlyFAME!F451=0,"",MonthlyFAME!F451) -> 19558 | F449: =IF(MonthlyFAME!G451=0,"",MonthlyFAME!G451) -> 17288 | G449: =IF(MonthlyFAME!H451=0,"",MonthlyFAME!H451) -> 7.669046 | H449: =IF(MonthlyFAME!I451=0,"",MonthlyFAME!I451) -> 26258 | I449: =IF(MonthlyFAME!J451=0,"",MonthlyFAME!J451) -> 867.8 | J449: 466.63636 | K449: =IF(MonthlyFAME!L451=0,"",MonthlyFAME!L451) -> 267.57221 | L449: =IF(MonthlyFAME!M451=0,"",MonthlyFAME!M451) -> 1818.4 | M449: =IF(MonthlyFAME!N451=0,"",MonthlyFAME!N451) | N449: =IF(MonthlyFAME!O451=0,"",MonthlyFAME!O451) | O449: =IF(MonthlyFAME!P451=0,"",MonthlyFAME!P451) | P449: =IF(MonthlyFAME!Q451=0,"",MonthlyFAME!Q451) | Q449: =IF(MonthlyFAME!R451=0,"",MonthlyFAME!R451) | R449: =IF(MonthlyFAME!S451=0,"",MonthlyFAME!S451) | ... T449: =IF(MonthlyFAME!U451=0,"",MonthlyFAME!U451) -> 23.472609
...

Sheet QuarterlyFAME
A2: 1960
A3: 2023 | B3: 1
A4: q | B4: GDP-q | C4: CONS | D4: INV | E4: HOURS
B5: abmi.q | C5: ons.uk.hhd.abjr.q | D5: ons.uk.ado.npqt.q | E5: ybus.q*13 | F5: a23_outputgap_fin.q | G5: a23_ckp_fin.q
A6: =[2]!FAMEData("FAMEDATE",A2,A3, 0,A4, "Down", "No Heading", "Normal") -> 22006 | B6: =[2]!FAMEData(B5, $A$2, $A$3, 0,$A$4,"Down","No Heading","Normal") -> 151420 | C6: =[2]!FAMEData(C5, $A$2, $A$3, 0,$A$4,"Down","No Heading","Normal") -> 77407 | D6: =[2]!FAMEData(D5, $A$2, $A$3, 0,$A$4,"Down","No Heading","Normal") -> 22788 | E6: =[2]!FAMEData(E5, $A$2, $A$3, 0,$A$4,"Down","No Heading","Normal") | F6: =[2]!FAMEData(F5, $A$2, $A$3, 0,$A$4,"Down","No Heading","Normal") | G6: =[2]!FAMEData(G5, $A$2, $A$3, 0,$A$4,"Down","No Heading","Normal")
A7: 22097 | B7: 150230 | C7: 77150 | D7: 23452
A8: 22189 | B8: 152485 | C8: 77664 | D8: 23888
A9: 22281 | B9: 153552 | C9: 77682 | D9: 24647
A10: 22371 | B10: 155990 | C10: 79058 | D10: 25266
A11: 22462 | B11: 156572 | C11: 79093 | D11: 25693
A12: 22554 | B12: 155818 | C12: 79472 | D12: 26062
A13: 22646 | B13: 155436 | C13: 79509 | D13: 25426
A14: 22736 | B14: 156202 | C14: 80153 | D14: 25626
A15: 22827 | B15: 157678 | C15: 81490 | D15: 26205
A16: 22919 | B16: 158572 | C16: 80962 | D16: 26085
A17: 23011 | B17: 157894 | C17: 81896 | D17: 25479
A18: 23101 | B18: 158616 | C18: 82351 | D18: 23515
... A49: 25933 | B49: 208869 | C49: 100058 | D49: 41365
A50: 26023 | B50: 207680 | C50: 99798 | D50: 40579 | E50: 11235.9
A51: 26114 | B51: 211465 | C51: 102036 | D51: 42575 | E51: 11216.4
A52: 26206 | B52: 215240 | C52: 103845 | D52: 43553 | E52: 11196.9
A53: 26298 | B53: 216006 | C53: 104685 | D53: 44186 | E53: 11202.1
A54: 26389 | B54: 216317 | C54: 106484 | D54: 43781 | E54: 11293.1
A55: 26480 | B55: 222086 | C55: 108905 | D55: 45230 | E55: 11350.3
A56: 26572 | B56: 222694 | C56: 110560 | D56: 45116 | E56: 11397.1
A57: 26664 | B57: 226205 | C57: 111472 | D57: 44980 | E57: 11464.7
A58: 26754 | B58: 237322 | C58: 115851 | D58: 47315 | E58: 11577.8
A59: 26845 | B59: 237728 | C59: 115074 | D59: 45755 | E59: 11624.6
A60: 26937 | B60: 235429 | C60: 115927 | D60: 44849 | E60: 11618.1
A61: 27029 | B61: 234514 | C61: 115008 | D61: 44646 | E61: 11620.7
... A114: 31867 | B114: 293128 | C114: 155439 | D114: 51615 | E114: 10873.2
A115: 31958 | B115: 297464 | C115: 158041 | D115: 54107 | E115: 10962.9 | G115: 163001
A116: 32050 | B116: 304555 | C116: 161305 | D116: 59096 | E116: 11079.9 | G116: 166402
A117: 32142 | B117: 308624 | C117: 164878 | D117: 60521 | E117: 11190.4 | G117: 170067
A118: 32233 | B118: 313316 | C118: 167118 | D118: 63524 | E118: 11302.2 | G118: 172527
A119: 32324 | B119: 313997 | C119: 169500 | D119: 65224 | E119: 11390.6 | G119: 174935
A120: 32416 | B120: 318223 | C120: 173440 | D120: 65803 | E120: 11480.3 | F120: 6.9176342 | G120: 178995
A121: 32508 | B121: 320612 | C121: 174977 | D121: 65739 | E121: 11572.6 | F121: 6.8467184 | G121: 180615
A122: 32598 | B122: 322258 | C122: 176456 | D122: 69251 | E122: 11685.7 | F122: 5.9973444 | G122: 182055
A123: 32689 | B123: 323569 | C123: 177960 | D123: 67897 | E123: 11753.3 | F123: 5.2760495 | G123: 183530
...

Sheet QuarterlyData
A2: 1960
A3: 2021 | B3: 1
A4: dates | B4: GDP_Q | C4: CONS | D4: INV | E4: HOURS
A5: =IF(QuarterlyFAME!A5=0,"",QuarterlyFAME!A5) | B5: =IF(QuarterlyFAME!B5=0,"",QuarterlyFAME!B5) -> abmi.q | C5: =IF(QuarterlyFAME!C5=0,"",QuarterlyFAME!C5) -> ons.uk.hhd.abjr.q | D5: =IF(QuarterlyFAME!D5=0,"",QuarterlyFAME!D5) -> ons.uk.ado.npqt.q | E5: =IF([3]QuarterlyFAME!E5=0,"",[3]QuarterlyFAME!E5) -> #REF!
A6: =IF(QuarterlyFAME!A6=0,"",QuarterlyFAME!A6) -> 22006 | B6: =IF(QuarterlyFAME!B6=0,"",QuarterlyFAME!B6) -> 151420 | C6: =IF(QuarterlyFAME!C6=0,"",QuarterlyFAME!C6) -> 77407 | D6: =IF(QuarterlyFAME!D6=0,"",QuarterlyFAME!D6) -> 22788 | E6: =IF([3]QuarterlyFAME!E6=0,"",[3]QuarterlyFAME!E6)
A7: =IF(QuarterlyFAME!A7=0,"",QuarterlyFAME!A7) -> 22097 | B7: =IF(QuarterlyFAME!B7=0,"",QuarterlyFAME!B7) -> 150230 | C7: =IF(QuarterlyFAME!C7=0,"",QuarterlyFAME!C7) -> 77150 | D7: =IF(QuarterlyFAME!D7=0,"",QuarterlyFAME!D7) -> 23452 | E7: =IF([3]QuarterlyFAME!E7=0,"",[3]QuarterlyFAME!E7)
A8: =IF(QuarterlyFAME!A8=0,"",QuarterlyFAME!A8) -> 22189 | B8: =IF(QuarterlyFAME!B8=0,"",QuarterlyFAME!B8) -> 152485 | C8: =IF(QuarterlyFAME!C8=0,"",QuarterlyFAME!C8) -> 77664 | D8: =IF(QuarterlyFAME!D8=0,"",QuarterlyFAME!D8) -> 23888 | E8: =IF([3]QuarterlyFAME!E8=0,"",[3]QuarterlyFAME!E8)
A9: =IF(QuarterlyFAME!A9=0,"",QuarterlyFAME!A9) -> 22281 | B9: =IF(QuarterlyFAME!B9=0,"",QuarterlyFAME!B9) -> 153552 | C9: =IF(QuarterlyFAME!C9=0,"",QuarterlyFAME!C9) -> 77682 | D9: =IF(QuarterlyFAME!D9=0,"",QuarterlyFAME!D9) -> 24647 | E9: =IF([3]QuarterlyFAME!E9=0,"",[3]QuarterlyFAME!E9)
A10: =IF(QuarterlyFAME!A10=0,"",QuarterlyFAME!A10) -> 22371 | B10: =IF(QuarterlyFAME!B10=0,"",QuarterlyFAME!B10) -> 155990 | C10: =IF(QuarterlyFAME!C10=0,"",QuarterlyFAME!C10) -> 79058 | D10: =IF(QuarterlyFAME!D10=0,"",QuarterlyFAME!D10) -> 25266 | E10: =IF([3]QuarterlyFAME!E10=0,"",[3]QuarterlyFAME!E10)
A11: =IF(QuarterlyFAME!A11=0,"",QuarterlyFAME!A11) -> 22462 | B11: =IF(QuarterlyFAME!B11=0,"",QuarterlyFAME!B11) -> 156572 | C11: =IF(QuarterlyFAME!C11=0,"",QuarterlyFAME!C11) -> 79093 | D11: =IF(QuarterlyFAME!D11=0,"",QuarterlyFAME!D11) -> 25693 | E11: =IF([3]QuarterlyFAME!E11=0,"",[3]QuarterlyFAME!E11)
A12: =IF(QuarterlyFAME!A12=0,"",QuarterlyFAME!A12) -> 22554 | B12: =IF(QuarterlyFAME!B12=0,"",QuarterlyFAME!B12) -> 155818 | C12: =IF(QuarterlyFAME!C12=0,"",QuarterlyFAME!C12) -> 79472 | D12: =IF(QuarterlyFAME!D12=0,"",QuarterlyFAME!D12) -> 26062 | E12: =IF([3]QuarterlyFAME!E12=0,"",[3]QuarterlyFAME!E12)
A13: =IF(QuarterlyFAME!A13=0,"",QuarterlyFAME!A13) -> 22646 | B13: =IF(QuarterlyFAME!B13=0,"",QuarterlyFAME!B13) -> 155436 | C13: =IF(QuarterlyFAME!C13=0,"",QuarterlyFAME!C13) -> 79509 | D13: =IF(QuarterlyFAME!D13=0,"",QuarterlyFAME!D13) -> 25426 | E13: =IF([3]QuarterlyFAME!E13=0,"",[3]QuarterlyFAME!E13)
A14: =IF(QuarterlyFAME!A14=0,"",QuarterlyFAME!A14) -> 22736 | B14: =IF(QuarterlyFAME!B14=0,"",QuarterlyFAME!B14) -> 156202 | C14: =IF(QuarterlyFAME!C14=0,"",QuarterlyFAME!C14) -> 80153 | D14: =IF(QuarterlyFAME!D14=0,"",QuarterlyFAME!D14) -> 25626 | E14: =IF([3]QuarterlyFAME!E14=0,"",[3]QuarterlyFAME!E14)
A15: =IF(QuarterlyFAME!A15=0,"",QuarterlyFAME!A15) -> 22827 | B15: =IF(QuarterlyFAME!B15=0,"",QuarterlyFAME!B15) -> 157678 | C15: =IF(QuarterlyFAME!C15=0,"",QuarterlyFAME!C15) -> 81490 | D15: =IF(QuarterlyFAME!D15=0,"",QuarterlyFAME!D15) -> 26205 | E15: =IF([3]QuarterlyFAME!E15=0,"",[3]QuarterlyFAME!E15)
A16: =IF(QuarterlyFAME!A16=0,"",QuarterlyFAME!A16) -> 22919 | B16: =IF(QuarterlyFAME!B16=0,"",QuarterlyFAME!B16) -> 158572 | C16: =IF(QuarterlyFAME!C16=0,"",QuarterlyFAME!C16) -> 80962 | D16: =IF(QuarterlyFAME!D16=0,"",QuarterlyFAME!D16) -> 26085 | E16: =IF([3]QuarterlyFAME!E16=0,"",[3]QuarterlyFAME!E16)
... A253: =IF(QuarterlyFAME!A253=0,"",QuarterlyFAME!A253) -> 44561 | B253: =IF(QuarterlyFAME!B253=0,"",QuarterlyFAME!B253) -> 554821 | C253: =IF(QuarterlyFAME!C253=0,"",QuarterlyFAME!C253) -> 333650 | D253: =IF(QuarterlyFAME!D253=0,"",QuarterlyFAME!D253) -> 96819 | E253: =IF([3]QuarterlyFAME!E253=0,"",[3]QuarterlyFAME!E253)
A254: =IF(QuarterlyFAME!A254=0,"",QuarterlyFAME!A254) -> 44651 | B254: =IF(QuarterlyFAME!B254=0,"",QuarterlyFAME!B254) -> 557524 | C254: =IF(QuarterlyFAME!C254=0,"",QuarterlyFAME!C254) -> 337725 | D254: =IF(QuarterlyFAME!D254=0,"",QuarterlyFAME!D254) -> 105123
A255: =IF(QuarterlyFAME!A255=0,"",QuarterlyFAME!A255) -> 44742 | B255: =IF(QuarterlyFAME!B255=0,"",QuarterlyFAME!B255) -> 557810 | C255: =IF(QuarterlyFAME!C255=0,"",QuarterlyFAME!C255) -> 338452 | D255: =IF(QuarterlyFAME!D255=0,"",QuarterlyFAME!D255) -> 102732
A256: =IF(QuarterlyFAME!A256=0,"",QuarterlyFAME!A256) -> 44834 | B256: =IF(QuarterlyFAME!B256=0,"",QuarterlyFAME!B256) -> 557286 | C256: =IF(QuarterlyFAME!C256=0,"",QuarterlyFAME!C256) -> 337395 | D256: =IF(QuarterlyFAME!D256=0,"",QuarterlyFAME!D256) -> 103858
A257: =IF(QuarterlyFAME!A257=0,"",QuarterlyFAME!A257) -> 44926 | B257: =IF(QuarterlyFAME!B257=0,"",QuarterlyFAME!B257) -> 558005 | C257: =IF(QuarterlyFAME!C257=0,"",QuarterlyFAME!C257) -> 338155 | D257: =IF(QuarterlyFAME!D257=0,"",QuarterlyFAME!D257) -> 104129
A258: =IF(QuarterlyFAME!A258=0,"",QuarterlyFAME!A258) -> 45016 | B258: =IF(QuarterlyFAME!B258=0,"",QuarterlyFAME!B258) -> 558812 | C258: =IF(QuarterlyFAME!C258=0,"",QuarterlyFAME!C258) -> 338285 | D258: =IF(QuarterlyFAME!D258=0,"",QuarterlyFAME!D258) -> 106661
A259: =IF(QuarterlyFAME!A259=0,"",QuarterlyFAME!A259) -> 45107 | B259: =IF(QuarterlyFAME!B259=0,"",QuarterlyFAME!B259) -> 559956 | C259: =IF(QuarterlyFAME!C259=0,"",QuarterlyFAME!C259) -> 340812 | D259: =IF(QuarterlyFAME!D259=0,"",QuarterlyFAME!D259) -> 106647
A260: =IF(QuarterlyFAME!A260=0,"",QuarterlyFAME!A260) -> 45199 | B260: =IF(QuarterlyFAME!B260=0,"",QuarterlyFAME!B260) | C260: =IF(QuarterlyFAME!C260=0,"",QuarterlyFAME!C260) | D260: =IF(QuarterlyFAME!D260=0,"",QuarterlyFAME!D260)
